2025-10-02 17:19:34,106 - ERROR - 500 Error: 500 Internal Server Error: The server encountered an internal error and was unable to complete your request. Either the server is overloaded or there is an error in the application.
2025-10-15 18:27:00,402 - WARNING - 404 at http://127.0.0.1:5000/static/css/output.min.css
2025-10-15 18:27:09,506 - ERROR - Exception on /reports/shops/1/reports/daily [GET]
Traceback (most recent call last):
  File "C:\Users\Admin\Desktop\projects\Grocery_saas\bhapos\Lib\site-packages\redis\connection.py", line 715, in connect
    sock = self.retry.call_with_retry(
        lambda: self._connect(), lambda error: self.disconnect(error)
    )
  File "C:\Users\Admin\Desktop\projects\Grocery_saas\bhapos\Lib\site-packages\redis\retry.py", line 46, in call_with_retry
    return do()
  File "C:\Users\Admin\Desktop\projects\Grocery_saas\bhapos\Lib\site-packages\redis\connection.py", line 716, in <lambda>
    lambda: self._connect(), lambda error: self.disconnect(error)
            ~~~~~~~~~~~~~^^
  File "C:\Users\Admin\Desktop\projects\Grocery_saas\bhapos\Lib\site-packages\redis\connection.py", line 781, in _connect
    raise err
  File "C:\Users\Admin\Desktop\projects\Grocery_saas\bhapos\Lib\site-packages\redis\connection.py", line 769, in _connect
    sock.connect(socket_address)
    ~~~~~~~~~~~~^^^^^^^^^^^^^^^^
ConnectionRefusedError: [WinError 10061] No connection could be made because the target machine actively refused it

During handling of the above exception, another exception occurred:

Traceback (most recent call last):
  File "C:\Users\Admin\Desktop\projects\Grocery_saas\bhapos\Lib\site-packages\flask\app.py", line 2077, in wsgi_app
    response = self.full_dispatch_request()
  File "C:\Users\Admin\Desktop\projects\Grocery_saas\bhapos\Lib\site-packages\flask\app.py", line 1525, in full_dispatch_request
    rv = self.handle_user_exception(e)
  File "C:\Users\Admin\Desktop\projects\Grocery_saas\bhapos\Lib\site-packages\flask\app.py", line 1523, in full_dispatch_request
    rv = self.dispatch_request()
  File "C:\Users\Admin\Desktop\projects\Grocery_saas\bhapos\Lib\site-packages\flask\app.py", line 1509, in dispatch_request
    return self.ensure_sync(self.view_functions[rule.endpoint])(**req.view_args)
           ~~~~~~~~~~~~~~~~~~~~~~~~~~~~~~~~~~~~~~~~~~~~~~~~~~~~^^^^^^^^^^^^^^^^^
  File "C:\Users\Admin\Desktop\projects\Grocery_saas\bhapos\Lib\site-packages\flask_login\utils.py", line 277, in decorated_view
    return current_app.ensure_sync(func)(*args, **kwargs)
           ~~~~~~~~~~~~~~~~~~~~~~~~~~~~~^^^^^^^^^^^^^^^^^
  File "C:\Users\Admin\Desktop\projects\Grocery_saas\app\__init__.py", line 79, in wrapped
    return view_func(*args, **kwargs)
  File "C:\Users\Admin\Desktop\projects\Grocery_saas\app\reports\routes.py", line 262, in daily_sales_report
    cached = cache.get(cache_key)
  File "C:\Users\Admin\Desktop\projects\Grocery_saas\bhapos\Lib\site-packages\flask_caching\__init__.py", line 195, in get
    return self.cache.get(*args, **kwargs)
           ~~~~~~~~~~~~~~^^^^^^^^^^^^^^^^^
  File "C:\Users\Admin\Desktop\projects\Grocery_saas\bhapos\Lib\site-packages\cachelib\redis.py", line 78, in get
    self._read_client.get(f"{self._get_prefix()}{key}")
    ~~~~~~~~~~~~~~~~~~~~~^^^^^^^^^^^^^^^^^^^^^^^^^^^^^^
  File "C:\Users\Admin\Desktop\projects\Grocery_saas\bhapos\Lib\site-packages\redis\commands\core.py", line 1790, in get
    return self.execute_command("GET", name)
           ~~~~~~~~~~~~~~~~~~~~^^^^^^^^^^^^^
  File "C:\Users\Admin\Desktop\projects\Grocery_saas\bhapos\Lib\site-packages\redis\client.py", line 1255, in execute_command
    conn = self.connection or pool.get_connection(command_name, **options)
                              ~~~~~~~~~~~~~~~~~~~^^^^^^^^^^^^^^^^^^^^^^^^^
  File "C:\Users\Admin\Desktop\projects\Grocery_saas\bhapos\Lib\site-packages\redis\connection.py", line 1481, in get_connection
    connection.connect()
    ~~~~~~~~~~~~~~~~~~^^
  File "C:\Users\Admin\Desktop\projects\Grocery_saas\bhapos\Lib\site-packages\redis\connection.py", line 721, in connect
    raise ConnectionError(self._error_message(e))
redis.exceptions.ConnectionError: Error 10061 connecting to localhost:6379. No connection could be made because the target machine actively refused it.
2025-10-15 18:27:09,564 - ERROR - 500 Error: 500 Internal Server Error: The server encountered an internal error and was unable to complete your request. Either the server is overloaded or there is an error in the application.
2025-10-15 18:50:04,075 - WARNING - 404 at http://127.0.0.1:5000/static/css/output.min.css
2025-10-15 18:50:06,911 - WARNING - 404 at http://127.0.0.1:5000/manifest.json
2025-10-15 18:50:07,143 - WARNING - 404 at http://127.0.0.1:5000/static/js/main.js
2025-10-15 18:50:07,271 - WARNING - 404 at http://127.0.0.1:5000/offline
2025-10-15 18:50:07,305 - WARNING - 404 at http://127.0.0.1:5000/static/images/logo.svg
2025-10-15 18:50:07,378 - WARNING - 404 at http://127.0.0.1:5000/static/fonts/Inter.woff2
2025-10-15 18:50:07,385 - WARNING - 404 at http://127.0.0.1:5000/static/offline-data.json
2025-10-15 18:50:13,198 - ERROR - Post-checkout task failed
2025-10-15 18:50:34,888 - ERROR - Post-checkout task failed
2025-10-15 18:51:16,441 - ERROR - Post-checkout task failed
2025-10-15 18:55:56,042 - WARNING - 404 at http://127.0.0.1:5000/manifest.json
2025-10-15 18:56:01,897 - ERROR - Post-checkout task failed
2025-10-16 13:25:16,741 - WARNING - 404 at http://127.0.0.1:5000/manifest.json
2025-10-16 13:25:16,834 - WARNING - 404 at http://127.0.0.1:5000/static/js/main.js
